<?xml version="1.0"?>
<robot name="quadog" xmlns:xacro="http://www.ros.org/wiki/xacro">

  <xacro:property name="hip_x_motor_torque" value="108.0"/>
  <xacro:property name="hip_x_motor_vel" value="18.9"/>
  <xacro:property name="hip_x_motor_lower_limit" value="-0.3839"/>
  <xacro:property name="hip_x_motor_upper_limit" value="0.3839"/>

  <xacro:property name="hip_y_motor_torque" value="140"/>
  <xacro:property name="hip_y_motor_vel" value="19"/>
  <xacro:property name="hip_y_motor_lower_limit" value="-0.1745"/>
  <xacro:property name="hip_y_motor_upper_limit" value="1.658"/>

  <xacro:property name="knee_motor_torque" value="140"/>
  <xacro:property name="knee_motor_vel" value="19"/>
  <xacro:property name="knee_motor_lower_limit" value="-2.7227"/>
  <xacro:property name="knee_motor_upper_limit" value="-0.6632"/>

  <xacro:property name="package_name" value="package://quadog_model"/>
  
  <xacro:property name="motor_damp" value="0.1"/>
  <xacro:property name="motor_friction" value="0.1"/>

  <xacro:property name="hip_x_link_mass" value="3.8044"/>
  <xacro:property name="hip_y_link_mass" value="5.5642"/>
  <xacro:property name="knee_link_mass" value="0.33298"/>

  <link name="base_link">
    </link>

  <joint name="base_link_joint" type="fixed">
    <origin
      xyz="0 0 0.65"
      rpy="0 0 0" />
    <parent link="base_link"/>
    <child link="Body_Link"/>
  </joint>

  <link
    name="Body_Link">
    <inertial>
      <origin
        xyz="0.01151 5.0984E-17 0.016155"
        rpy="0 0 0" />
      <mass
        value="29.667" />
      <inertia
        ixx="0.21965"
        ixy="-2.7726E-06"
        ixz="-0.037233"
        iyy="1.3704"
        iyz="8.7205E-18"
        izz="1.4281" />
    </inertial>
    <visual>
      <origin
        xyz="0 0 0"
        rpy="0 0 0" />
      <geometry>
        <mesh
          filename="${package_name}/meshes/Body_Link.STL" />
      </geometry>
      <material
        name="">
        <color
          rgba="0.79216 0.81961 0.93333 1" />
      </material>
    </visual>
    <collision>
      <origin
        xyz="0 0 0"
        rpy="0 0 0" />
      <geometry>
        <mesh
          filename="${package_name}/meshes/Body_Link.STL" />
      </geometry>
    </collision>
  </link>
  <link
    name="FLHipX_Link">
    <inertial>
      <origin
        xyz="-5.7744E-09 -0.029179 -4.2593E-09"
        rpy="0 0 0" />
      <mass
        value="${hip_x_link_mass}" />
      <inertia
        ixx="0.0034294"
        ixy="-2.5472E-09"
        ixz="6.2073E-10"
        iyy="0.0046349"
        iyz="4.0148E-10"
        izz="0.0037065" />
    </inertial>
    <visual>
      <origin
        xyz="0 0 0"
        rpy="0 0 0" />
      <geometry>
        <mesh
          filename="${package_name}/meshes/FLHipX_Link.STL" />
      </geometry>
      <material
        name="">
        <color
          rgba="0.64706 0.61961 0.58824 1" />
      </material>
    </visual>
    <collision>
      <origin
        xyz="0 0 0"
        rpy="0 0 0" />
      <geometry>
        <mesh
          filename="${package_name}/meshes/FLHipX_Link.STL" />
      </geometry>
    </collision>
  </link>
  <joint
    name="FLHipX"
    type="revolute">
    <origin
      xyz="0.3175 0.136 0"
      rpy="0 0 0" />
    <parent
      link="Body_Link" />
    <child
      link="FLHipX_Link" />
    <axis
      xyz="1 0 0" />
    <limit
      lower="${hip_x_motor_lower_limit}"
      upper="${hip_x_motor_upper_limit}"
      effort="${hip_x_motor_torque}"
      velocity="${hip_x_motor_vel}" />
    <dynamics
      damping="${motor_damp}"
      friction="${motor_friction}" />
  </joint>
  <link
    name="FLHipY_Link">
    <inertial>
      <origin
        xyz="6.1702E-09 0.00113 -0.058499"
        rpy="0 0 0" />
      <mass
        value="${hip_y_link_mass}" />
      <inertia
        ixx="0.039798"
        ixy="-2.3659E-09"
        ixz="3.4687E-09"
        iyy="0.040888"
        iyz="-0.00036845"
        izz="0.0037562" />
    </inertial>
    <visual>
      <origin
        xyz="0 0 0"
        rpy="0 0 0" />
      <geometry>
        <mesh
          filename="${package_name}/meshes/FLHipY_Link.STL" />
      </geometry>
      <material
        name="">
        <color
          rgba="0.61569 0.64314 0.67451 1" />
      </material>
    </visual>
    <collision>
      <origin
        xyz="0 0 0"
        rpy="0 0 0" />
      <geometry>
        <mesh
          filename="${package_name}/meshes/FLHipY_Link.STL" />
      </geometry>
    </collision>
  </link>
  <joint
    name="FLHipY"
    type="revolute">
    <origin
      xyz="0 0.0370000000000001 0"
      rpy="0 0 0" />
    <parent
      link="FLHipX_Link" />
    <child
      link="FLHipY_Link" />
    <axis
      xyz="0 1 0" />
    <limit
      lower="${hip_y_motor_lower_limit}"
      upper="${hip_y_motor_upper_limit}"
      effort="${hip_y_motor_torque}"
      velocity="${hip_y_motor_torque}" />
    <dynamics
      damping="${motor_damp}"
      friction="${motor_friction}" />
  </joint>
  <link
    name="FLKnee_Link">
    <inertial>
      <origin
        xyz="0 -8.3267E-17 -0.16377"
        rpy="0 0 0" />
      <mass
        value="${knee_link_mass}" />
      <inertia
        ixx="0.0041845"
        ixy="3.1098E-10"
        ixz="1.693E-18"
        iyy="0.0042044"
        iyz="-6.8865E-19"
        izz="7.2362E-05" />
    </inertial>
    <visual>
      <origin
        xyz="0 0 0"
        rpy="0 0 0" />
      <geometry>
        <mesh
          filename="${package_name}/meshes/FLKnee_Link.STL" />
      </geometry>
      <material
        name="">
        <color
          rgba="0.79216 0.81961 0.93333 1" />
      </material>
    </visual>
    <collision>
      <origin
        xyz="0 0 0"
        rpy="0 0 0" />
      <geometry>
        <mesh
          filename="${package_name}/meshes/FLKnee_Link.STL" />
      </geometry>
    </collision>
  </link>
  <joint
    name="FLKnee"
    type="revolute">
    <origin
      xyz="0 0 -0.3"
      rpy="0 0 0" />
    <parent
      link="FLHipY_Link" />
    <child
      link="FLKnee_Link" />
    <axis
      xyz="0 1 0" />
    <limit
      lower="${knee_motor_lower_limit}"
      upper="${knee_motor_upper_limit}"
      effort="${knee_motor_torque}"
      velocity="${knee_motor_vel}" />
    <dynamics
      damping="${motor_damp}"
      friction="${motor_friction}" />
  </joint>
  <link
    name="HLHipX_Link">
    <inertial>
      <origin
        xyz="-5.7744E-09 -0.029179 -4.2593E-09"
        rpy="0 0 0" />
      <mass
        value="${hip_x_link_mass}" />
      <inertia
        ixx="0.0034294"
        ixy="-2.5472E-09"
        ixz="6.2073E-10"
        iyy="0.0046349"
        iyz="4.0148E-10"
        izz="0.0037065" />
    </inertial>
    <visual>
      <origin
        xyz="0 0 0"
        rpy="0 0 0" />
      <geometry>
        <mesh
          filename="${package_name}/meshes/HLHipX_Link.STL" />
      </geometry>
      <material
        name="">
        <color
          rgba="0.64706 0.61961 0.58824 1" />
      </material>
    </visual>
    <collision>
      <origin
        xyz="0 0 0"
        rpy="0 0 0" />
      <geometry>
        <mesh
          filename="${package_name}/meshes/HLHipX_Link.STL" />
      </geometry>
    </collision>
  </link>
  <joint
    name="HLHipX"
    type="revolute">
    <origin
      xyz="-0.3175 0.136 0"
      rpy="0 0 0" />
    <parent
      link="Body_Link" />
    <child
      link="HLHipX_Link" />
    <axis
      xyz="1 0 0" />
    <limit
      lower="${hip_x_motor_lower_limit}"
      upper="${hip_x_motor_upper_limit}"
      effort="${hip_x_motor_torque}"
      velocity="${hip_x_motor_vel}" />
    <dynamics
      damping="${motor_damp}"
      friction="${motor_friction}" />
  </joint>
  <link
    name="HLHipY_Link">
    <inertial>
      <origin
        xyz="6.1702E-09 0.00113 -0.058499"
        rpy="0 0 0" />
      <mass
        value="${hip_y_link_mass}" />
      <inertia
        ixx="0.039798"
        ixy="-2.3659E-09"
        ixz="3.4687E-09"
        iyy="0.040888"
        iyz="-0.00036845"
        izz="0.0037562" />
    </inertial>
    <visual>
      <origin
        xyz="0 0 0"
        rpy="0 0 0" />
      <geometry>
        <mesh
          filename="${package_name}/meshes/HLHipY_Link.STL" />
      </geometry>
      <material
        name="">
        <color
          rgba="0.61569 0.64314 0.67451 1" />
      </material>
    </visual>
    <collision>
      <origin
        xyz="0 0 0"
        rpy="0 0 0" />
      <geometry>
        <mesh
          filename="${package_name}/meshes/HLHipY_Link.STL" />
      </geometry>
    </collision>
  </link>
  <joint
    name="HLHipY"
    type="revolute">
    <origin
      xyz="0 0.037 0"
      rpy="0 0 0" />
    <parent
      link="HLHipX_Link" />
    <child
      link="HLHipY_Link" />
    <axis
      xyz="0 1 0" />
    <limit
      lower="${hip_y_motor_lower_limit}"
      upper="${hip_y_motor_upper_limit}"
      effort="${hip_y_motor_torque}"
      velocity="${hip_y_motor_torque}" />
    <dynamics
      damping="${motor_damp}"
      friction="${motor_friction}" />
  </joint>
  <link
    name="HLKnee_Link">
    <inertial>
      <origin
        xyz="0 0 -0.16377"
        rpy="0 0 0" />
      <mass
        value="${knee_link_mass}" />
      <inertia
        ixx="0.0041845"
        ixy="3.1098E-10"
        ixz="1.4157E-18"
        iyy="0.0042044"
        iyz="-8.7851E-19"
        izz="7.2362E-05" />
    </inertial>
    <visual>
      <origin
        xyz="0 0 0"
        rpy="0 0 0" />
      <geometry>
        <mesh
          filename="${package_name}/meshes/HLKnee_Link.STL" />
      </geometry>
      <material
        name="">
        <color
          rgba="0.79216 0.81961 0.93333 1" />
      </material>
    </visual>
    <collision>
      <origin
        xyz="0 0 0"
        rpy="0 0 0" />
      <geometry>
        <mesh
          filename="${package_name}/meshes/HLKnee_Link.STL" />
      </geometry>
    </collision>
  </link>
  <joint
    name="HLKnee"
    type="revolute">
    <origin
      xyz="0 0 -0.3"
      rpy="0 0 0" />
    <parent
      link="HLHipY_Link" />
    <child
      link="HLKnee_Link" />
    <axis
      xyz="0 1 0" />
    <limit
      lower="${knee_motor_lower_limit}"
      upper="${knee_motor_upper_limit}"
      effort="${knee_motor_torque}"
      velocity="${knee_motor_vel}" />
    <dynamics
      damping="${motor_damp}"
      friction="${motor_friction}" />
  </joint>
  <link
    name="FRHipX_Link">
    <inertial>
      <origin
        xyz="-5.7744E-09 0.029179 4.2593E-09"
        rpy="0 0 0" />
      <mass
        value="${hip_x_link_mass}" />
      <inertia
        ixx="0.0034294"
        ixy="2.5472E-09"
        ixz="-6.2073E-10"
        iyy="0.0046349"
        iyz="4.0148E-10"
        izz="0.0037065" />
    </inertial>
    <visual>
      <origin
        xyz="0 0 0"
        rpy="0 0 0" />
      <geometry>
        <mesh
          filename="${package_name}/meshes/FRHipX_Link.STL" />
      </geometry>
      <material
        name="">
        <color
          rgba="0.64706 0.61961 0.58824 1" />
      </material>
    </visual>
    <collision>
      <origin
        xyz="0 0 0"
        rpy="0 0 0" />
      <geometry>
        <mesh
          filename="${package_name}/meshes/FRHipX_Link.STL" />
      </geometry>
    </collision>
  </link>
  <joint
    name="FRHipX"
    type="revolute">
    <origin
      xyz="0.3175 -0.136 0"
      rpy="0 0 0" />
    <parent
      link="Body_Link" />
    <child
      link="FRHipX_Link" />
    <axis
      xyz="1 0 0" />
    <limit
      lower="${hip_x_motor_lower_limit}"
      upper="${hip_x_motor_upper_limit}"
      effort="${hip_x_motor_torque}"
      velocity="${hip_x_motor_vel}" />
    <dynamics
      damping="${motor_damp}"
      friction="${motor_friction}" />
  </joint>
  <link
    name="FRHipY_Link">
    <inertial>
      <origin
        xyz="-6.1702E-09 -0.00113 -0.058499"
        rpy="0 0 0" />
      <mass
        value="${hip_y_link_mass}" />
      <inertia
        ixx="0.039798"
        ixy="-2.3659E-09"
        ixz="-3.4687E-09"
        iyy="0.040888"
        iyz="0.00036845"
        izz="0.0037562" />
    </inertial>
    <visual>
      <origin
        xyz="0 0 0"
        rpy="0 0 0" />
      <geometry>
        <mesh
          filename="${package_name}/meshes/FRHipY_Link.STL" />
      </geometry>
      <material
        name="">
        <color
          rgba="0.61569 0.64314 0.67451 1" />
      </material>
    </visual>
    <collision>
      <origin
        xyz="0 0 0"
        rpy="0 0 0" />
      <geometry>
        <mesh
          filename="${package_name}/meshes/FRHipY_Link.STL" />
      </geometry>
    </collision>
  </link>
  <joint
    name="FRHipY"
    type="revolute">
    <origin
      xyz="0 -0.037 0"
      rpy="0 0 0" />
    <parent
      link="FRHipX_Link" />
    <child
      link="FRHipY_Link" />
    <axis
      xyz="0 1 0" />
    <limit
      lower="${hip_y_motor_lower_limit}"
      upper="${hip_y_motor_upper_limit}"
      effort="${hip_y_motor_torque}"
      velocity="${hip_y_motor_torque}" />
    <dynamics
      damping="${motor_damp}"
      friction="${motor_friction}" />
  </joint>
  <link
    name="FRKnee_Link">
    <inertial>
      <origin
        xyz="1.1102E-16 1.3878E-16 -0.16377"
        rpy="0 0 0" />
      <mass
        value="${knee_link_mass}" />
      <inertia
        ixx="0.0041845"
        ixy="3.1098E-10"
        ixz="-9.8165E-19"
        iyy="0.0042044"
        iyz="-4.3862E-19"
        izz="7.2362E-05" />
    </inertial>
    <visual>
      <origin
        xyz="0 0 0"
        rpy="0 0 0" />
      <geometry>
        <mesh
          filename="${package_name}/meshes/FRKnee_Link.STL" />
      </geometry>
      <material
        name="">
        <color
          rgba="0.79216 0.81961 0.93333 1" />
      </material>
    </visual>
    <collision>
      <origin
        xyz="0 0 0"
        rpy="0 0 0" />
      <geometry>
        <mesh
          filename="${package_name}/meshes/FRKnee_Link.STL" />
      </geometry>
    </collision>
  </link>
  <joint
    name="FRKnee"
    type="revolute">
    <origin
      xyz="0 0 -0.3"
      rpy="0 0 0" />
    <parent
      link="FRHipY_Link" />
    <child
      link="FRKnee_Link" />
    <axis
      xyz="0 1 0" />
    <limit
      lower="${knee_motor_lower_limit}"
      upper="${knee_motor_upper_limit}"
      effort="${knee_motor_torque}"
      velocity="${knee_motor_vel}" />
    <dynamics
      damping="${motor_damp}"
      friction="${motor_friction}" />
  </joint>
  <link
    name="HRHipX_Link">
    <inertial>
      <origin
        xyz="0 0 0"
        rpy="0 0 0" />
      <mass
        value="${hip_x_link_mass}" />
      <inertia
        ixx="0.0034294"
        ixy="2.5472E-09"
        ixz="-6.2073E-10"
        iyy="0.0046349"
        iyz="4.0148E-10"
        izz="0.0037065" />
    </inertial>
    <visual>
      <origin
        xyz="0 0 0"
        rpy="0 0 0" />
      <geometry>
        <mesh
          filename="${package_name}/meshes/HRHipX_Link.STL" />
      </geometry>
      <material
        name="">
        <color
          rgba="1 1 1 1" />
      </material>
    </visual>
    <collision>
      <origin
        xyz="0 0 0"
        rpy="0 0 0" />
      <geometry>
        <mesh
          filename="${package_name}/meshes/HRHipX_Link.STL" />
      </geometry>
    </collision>
  </link>
  <joint
    name="HRHipX"
    type="revolute">
    <origin
      xyz="-0.3175 -0.136 0"
      rpy="0 0 0" />
    <parent
      link="Body_Link" />
    <child
      link="HRHipX_Link" />
    <axis
      xyz="1 0 0" />
    <limit
      lower="${hip_x_motor_lower_limit}"
      upper="${hip_x_motor_upper_limit}"
      effort="${hip_x_motor_torque}"
      velocity="${hip_x_motor_vel}" />
    <dynamics
      damping="${motor_damp}"
      friction="${motor_friction}" />
  </joint>
  <link
    name="HRHipY_Link">
    <inertial>
      <origin
        xyz="-6.1702E-09 -0.00113 -0.058499"
        rpy="0 0 0" />
      <mass
        value="${hip_y_link_mass}" />
      <inertia
        ixx="0.039798"
        ixy="-2.3659E-09"
        ixz="-3.4687E-09"
        iyy="0.040888"
        iyz="0.00036845"
        izz="0.0037562" />
    </inertial>
    <visual>
      <origin
        xyz="0 0 0"
        rpy="0 0 0" />
      <geometry>
        <mesh
          filename="${package_name}/meshes/HRHipY_Link.STL" />
      </geometry>
      <material
        name="">
        <color
          rgba="0.61569 0.64314 0.67451 1" />
      </material>
    </visual>
    <collision>
      <origin
        xyz="0 0 0"
        rpy="0 0 0" />
      <geometry>
        <mesh
          filename="${package_name}/meshes/HRHipY_Link.STL" />
      </geometry>
    </collision>
  </link>
  <joint
    name="HRHipY"
    type="revolute">
    <origin
      xyz="0 -0.037 0"
      rpy="0 0 0" />
    <parent
      link="HRHipX_Link" />
    <child
      link="HRHipY_Link" />
    <axis
      xyz="0 1 0" />
    <limit
      lower="${hip_y_motor_lower_limit}"
      upper="${hip_y_motor_upper_limit}"
      effort="${hip_y_motor_torque}"
      velocity="${hip_y_motor_vel}" />
    <dynamics
      damping="${motor_damp}"
      friction="${motor_friction}" />
  </joint>
  <link
    name="HRKnee_Link">
    <inertial>
      <origin
        xyz="5.5511E-17 -2.7756E-17 -0.16377"
        rpy="0 0 0" />
      <mass
        value="${knee_link_mass}" />
      <inertia
        ixx="0.0041845"
        ixy="3.1098E-10"
        ixz="1.5955E-18"
        iyy="0.0042044"
        iyz="-4.4296E-19"
        izz="7.2362E-05" />
    </inertial>
    <visual>
      <origin
        xyz="0 0 0"
        rpy="0 0 0" />
      <geometry>
        <mesh
          filename="${package_name}/meshes/HRKnee_Link.STL" />
      </geometry>
      <material
        name="">
        <color
          rgba="0.79216 0.81961 0.93333 1" />
      </material>
    </visual>
    <collision>
      <origin
        xyz="0 0 0"
        rpy="0 0 0" />
      <geometry>
        <mesh
          filename="${package_name}/meshes/HRKnee_Link.STL" />
      </geometry>
    </collision>
  </link>
  <joint
    name="HRKnee"
    type="revolute">
    <origin
      xyz="0 0 -0.3"
      rpy="0 0 0" />
    <parent
      link="HRHipY_Link" />
    <child
      link="HRKnee_Link" />
    <axis
      xyz="0 1 0" />
    <limit
      lower="${knee_motor_lower_limit}"
      upper="${knee_motor_upper_limit}"
      effort="${knee_motor_torque}"
      velocity="${knee_motor_vel}" />
    <dynamics
      damping="${motor_damp}"
      friction="${motor_friction}" />
  </joint>
</robot>
